Workbook

Sheet Análise de dados
A2: Análise de base de dados abertos
A3: Análise de dados baseada em perguntas orientadoras.
A6: 1- Comparativo entre o valor adicionado total de SJC pelo PIB entre 2020 e 2021
A8: Ano | B8: Total do valor adicionado | C8: PIB | D8: Diferença percentual
A9: 2020 | B9: ='Tabela 1'!E16 -> 106.09495 | C9: ='Tabela 1'!F16 -> 121.94684 | D9: =(C9/B9)/C9 -> 0.0094255195
A10: 2021 | B10: ='Tabela 1'!J16 -> 137.01078 | C10: ='Tabela 1'!K16 -> 157.33092 | D10: =(C10/B10)/C10 -> 0.0072986955
A23: 2- Média do valor adicionado SJC em todos os anos
A25: Total PIB | B25: Indústria | C25: Serviços | D25: Agropecuária
A26: =AVERAGE('Tabela 17.8'!G8:G92) -> 2.3866298 | B26: =AVERAGE('Tabela 17.8'!D8:D92) -> 0.82562572 | C26: =AVERAGE('Tabela 17.8'!E8:E92) -> 2.7389955 | D26: =AVERAGE('Tabela 17.8'!C8:C92) -> 1.7447652
A40: 3- Evolução do crescimento do PIB em 2024
A42: Trimestres | B42: Trimestre / Trimestre imediatamente anterior (com ajuste sazonal) | C42: Trimestre / mesmo trimestre do ano anterior
A43: 2024.1 | B43: 1.7401157 | C43: 3.4116089
A44: 2024.2 | B44: 1.9037326 | C44: 5.435507
A45: 2024.3 | B45: 0.31210674 | C45: 5.3303137
A46: 2024.4 | B46: -0.34748233 | C46: 3.8342092
A57: 4- Quais municípios estão abaixo da média do PIB?
A59: Municípios: | B59: PIB Município | D59: Média PIB
A60: RM São Paulo | B60: =VLOOKUP(A60,'Tabela 1'!$A$9:$F$29,6,FALSE) -> 1236.6581 | D60: =AVERAGE('Tabela 1'!F9:F29) -> 285.33029
A61: Município de São Paulo | B61: =VLOOKUP(A61,'Tabela 1'!A10:F30,6,FALSE) -> 746.90933
A62: RA Campinas | B62: =VLOOKUP(A62,'Tabela 1'!A14:F34,6,FALSE) -> 458.38682
A63: Região de Osasco | B63: =VLOOKUP(A63,'Tabela 1'!A13:F33,6,FALSE) -> 238.13918
A64: Região do ABCD | B64: =VLOOKUP(A64,'Tabela 1'!A11:F31,6,FALSE) -> 127.203
A65: Região de Guarulhos | B65: =VLOOKUP(A65,'Tabela 1'!A12:F32,6,FALSE) -> 124.4066
A66: RA São José dos Campos | B66: =VLOOKUP(A66,'Tabela 1'!A15:F35,6,FALSE) -> 121.94684
A67: RA Sorocaba | B67: =VLOOKUP(A67,'Tabela 1'!A16:F36,6,FALSE) -> 112.90937
A68: RA Santos | B68: =VLOOKUP(A68,'Tabela 1'!A17:F37,6,FALSE) -> 68.481915
A69: RA Ribeirão Preto | B69: =VLOOKUP(A69,'Tabela 1'!A18:F38,6,FALSE) -> 62.481005
A70: RA São José do Rio Preto | B70: =VLOOKUP(A70,'Tabela 1'!A19:F39,6,FALSE) -> 58.763537
A71: RA Bauru | B71: =VLOOKUP(A71,'Tabela 1'!A20:F40,6,FALSE) -> 48.296824
A72: RA Central | B72: =VLOOKUP(A72,'Tabela 1'!A21:F41,6,FALSE) -> 44.342566
A73: RA Marília | B73: =VLOOKUP(A73,'Tabela 1'!A22:F42,6,FALSE) -> 37.528086
A74: RA Presidente Prudente | B74: =VLOOKUP(A74,'Tabela 1'!A23:F43,6,FALSE) -> 28.24778
A75: RA Franca | B75: =VLOOKUP(A75,'Tabela 1'!A25:F45,6,FALSE) -> 27.782516
A76: RA Araçatuba | B76: =VLOOKUP(A76,'Tabela 1'!A24:F44,6,FALSE) -> 27.537034
A77: RA Barretos | B77: =VLOOKUP(A77,'Tabela 1'!A27:F47,6,FALSE) -> 17.74211
A78: RA Itapeva | B78: =VLOOKUP(A78,'Tabela 1'!A26:F46,6,FALSE) -> 17.510092
A79: RA Registro | B79: =VLOOKUP(A79,'Tabela 1'!A28:F48,6,FALSE) -> 9.0243726
A81: 5- Qual a participação (em %) do PIB das cidades comparado com o Estado de SP?
A83: Municípios: | B83: PIB Cidades | C83: Particpação do PIB total: | E83: PIB Total:
A84: Município de São Paulo | B84: =VLOOKUP(A84,'Tabela 1'!A8:F29,6,FALSE) -> 746.90933 | C84: =(B84/$E$84) -> 0.31413908 | E84: 2377.639
...

Sheet Tabela 1
A1: Tabela 1
A2: Valor Adicionado por setores e Produto Interno Bruto, segundo as regiões administrativas
A3: Estado de São Paulo
A4: 2020-2024
Z5: Em R$ bilhões
B6: 2020 | G6: 2021 | L6: 2022 | Q6: 2023 | V6: 2024
B7: Valor Adicionado | G7: Valor Adicionado | L7: Valor Adicionado | P7: PIB | Q7: Valor Adicionado | V7: Valor Adicionado
A8: Regiões Administrativas | B8: Agropecuária | C8: Indústria | D8: Serviços | E8: Total | F8: PIB | G8: Agropecuária | H8: Indústria | I8: Serviços | J8: Total | K8: PIB | L8: Agropecuária | M8: Indústria | N8: Serviços | O8: Total | Q8: Agropecuária | R8: Indústria | S8: Serviços | T8: Total | U8: PIB | V8: Agropecuária | W8: Indústria | X8: Serviços | Y8: Total | Z8: PIB
A9: Estado de São Paulo | B9: 44.391205 | C9: 416.87301 | D9: 1553.5861 | E9: 2014.8503 | F9: 2377.639 | G9: 46.193518 | H9: 518.29253 | I9: 1681.8794 | J9: 2246.3654 | K9: 2719.7512 | L9: 42.392265 | M9: 641.85328 | N9: 1948.4454 | O9: 2632.6909 | P9: 3130.3332 | Q9: 41.439985 | R9: 610.12476 | S9: 2097.3243 | T9: 2748.8891 | U9: 3235.3148 | V9: 44.335482 | W9: 627.52465 | X9: 2254.4626 | Y9: 2926.3227 | Z9: 3480.9458
A10: RM São Paulo | B10: 2.0410631 | C10: 142.66712 | D10: 885.60154 | E10: 1030.3097 | F10: 1236.6581 | G10: 1.9810301 | H10: 168.35213 | I10: 945.09477 | J10: 1115.4279 | K10: 1390.1028 | L10: 1.642145 | M10: 197.4374 | N10: 1095.9992 | O10: 1295.0787 | P10: 1582.9595 | Q10: 1.1915284 | R10: 199.1166 | S10: 1193.5073 | T10: 1393.8154 | U10: 1677.9026 | V10: 1.1611819 | W10: 209.77103 | X10: 1294.1261 | Y10: 1505.0583 | Z10: 1827.0287
A11: Município de São Paulo | B11: 0.061896496 | C11: 57.439419 | D11: 565.0784 | E11: 622.57971 | F11: 746.90933 | G11: 0.061628253 | H11: 62.513855 | I11: 598.2211 | J11: 660.79658 | K11: 828.98061 | L11: 0.048301792 | M11: 70.058264 | N11: 692.45268 | O11: 762.55925 | P11: 937.1345 | Q11: 0.039508388 | R11: 74.432204 | S11: 769.3318 | T11: 843.80352 | U11: 1019.6451 | V11: 0.039570197 | W11: 79.096097 | X11: 840.13143 | Y11: 919.2671 | Z11: 1117.367
A12: Região do ABCD | B12: 0.016250191 | C12: 29.683087 | D12: 77.724161 | E12: 107.4235 | F12: 127.203 | G12: 0.016376167 | H12: 38.503718 | I12: 85.825819 | J12: 124.34591 | K12: 150.57638 | L12: 0.012500609 | M12: 48.208353 | N12: 96.222037 | O12: 144.44289 | P12: 171.07356 | Q12: 0.0029909681 | R12: 46.110935 | S12: 101.53953 | T12: 147.65346 | U12: 173.41898 | V12: 0.0029546187 | W12: 49.353738 | X12: 108.72555 | Y12: 158.08224 | Z12: 188.47468
A13: Região de Guarulhos | B13: 1.7027214 | C13: 26.906489 | D13: 76.815875 | E13: 105.42509 | F13: 124.4066 | G13: 1.6554234 | H13: 34.609567 | I13: 83.758683 | J13: 120.02367 | K13: 144.83184 | L13: 1.3888033 | M13: 41.565865 | N13: 99.576414 | O13: 142.53108 | P13: 169.62285 | Q13: 1.0051444 | R13: 41.080647 | S13: 104.96458 | T13: 147.05037 | U13: 172.61087 | V13: 0.97300674 | W13: 41.848536 | X13: 109.97833 | Y13: 152.79988 | Z13: 181.78759
A14: Região de Osasco | B14: 0.26019502 | C14: 28.638122 | D14: 165.9831 | E14: 194.88142 | F14: 238.13918 | G14: 0.24760234 | H14: 32.724992 | I14: 177.28916 | J14: 210.26176 | K14: 265.71395 | L14: 0.19253937 | M14: 37.604916 | N14: 207.74804 | O14: 245.54549 | P14: 305.1286 | Q14: 0.14388457 | R14: 37.492816 | S14: 217.6714 | T14: 255.3081 | U14: 312.22765 | V14: 0.14565033 | W14: 39.472659 | X14: 235.29074 | Y14: 274.90905 | Z14: 339.39936
A15: RA Campinas | B15: 7.5339475 | C15: 120.28108 | D15: 251.45847 | E15: 379.27349 | F15: 458.38682 | G15: 8.6216052 | H15: 149.45972 | I15: 278.10534 | J15: 436.18666 | K15: 535.6639 | L15: 8.4755728 | M15: 184.05519 | N15: 319.31432 | O15: 511.84509 | P15: 617.0445 | Q15: 8.2076143 | R15: 173.44108 | S15: 337.00384 | T15: 518.65253 | U15: 619.25106 | V15: 10.721379 | W15: 175.17561 | X15: 360.72468 | Y15: 546.62167 | Z15: 662.47682
A16: RA São José dos Campos | B16: 0.57212874 | C16: 39.848668 | D16: 65.674152 | E16: 106.09495 | F16: 121.94684 | G16: 0.62652656 | H16: 61.183658 | I16: 75.2006 | J16: 137.01078 | K16: 157.33092 | L16: 0.66832636 | M16: 83.20433 | N16: 86.156071 | O16: 170.02873 | P16: 184.90461 | Q16: 0.54020406 | R16: 71.09136 | S16: 90.107221 | T16: 161.73879 | U16: 175.881 | V16: 0.78135493 | W16: 69.41059 | X16: 94.596887 | Y16: 164.78883 | Z16: 181.74255
A17: RA Sorocaba | B17: 4.1700381 | C17: 26.847086 | D17: 64.555591 | E17: 95.572715 | F17: 112.90937 | G17: 4.2975388 | H17: 35.5442 | I17: 72.60134 | J17: 112.44308 | K17: 135.34799 | L17: 3.6407757 | M17: 44.490532 | N17: 84.351241 | O17: 132.48255 | P17: 157.19589 | Q17: 4.221134 | R17: 41.559688 | S17: 91.733286 | T17: 137.51411 | U17: 162.23638 | V17: 4.415338 | W17: 43.303562 | X17: 96.839643 | Y17: 144.55854 | Z17: 172.91576
A18: RA Santos | B18: 0.15717602 | C18: 13.62975 | D18: 46.807036 | E18: 60.593963 | F18: 68.481915 | G18: 0.1754709 | H18: 17.980347 | I18: 51.116599 | J18: 69.272418 | K18: 79.037792 | L18: 0.1480626 | M18: 27.955026 | N18: 59.657185 | O18: 87.760274 | P18: 97.273671 | Q18: 0.16724607 | R18: 21.434569 | S18: 63.217617 | T18: 84.819433 | U18: 94.637101 | V18: 0.16274515 | W18: 22.088408 | X18: 66.114608 | Y18: 88.365761 | Z18: 99.76843
A19: RA Ribeirão Preto | B19: 2.3007603 | C19: 10.467088 | D19: 42.860964 | E19: 55.628812 | F19: 62.481005 | G19: 2.5421203 | H19: 12.734704 | I19: 46.356367 | J19: 61.633191 | K19: 70.272389 | L19: 2.3840011 | M19: 15.181234 | N19: 53.825826 | O19: 71.391061 | P19: 81.066842 | Q19: 2.1815779 | R19: 15.039151 | S19: 56.873644 | T19: 74.094373 | U19: 82.950469 | V19: 2.315264 | W19: 15.809712 | X19: 62.291723 | Y19: 80.416699 | Z19: 90.940203
A20: RA São José do Rio Preto | B20: 4.3759222 | C20: 10.105976 | D20: 39.07383 | E20: 53.555728 | F20: 58.763537 | G20: 4.5621969 | H20: 11.086824 | I20: 42.507354 | J20: 58.156374 | K20: 64.810406 | L20: 4.3413491 | M20: 13.02172 | N20: 49.496499 | O20: 66.859568 | P20: 74.871908 | Q20: 4.4917902 | R20: 13.437578 | S20: 53.018678 | T20: 70.948046 | U20: 78.649861 | V20: 4.5990306 | W20: 13.997057 | X20: 56.860254 | Y20: 75.456342 | Z20: 84.353658
... A29: RA Registro | B29: 1.2949423 | C29: 1.7032313 | D29: 5.3893315 | E29: 8.3875052 | F29: 9.0243726 | G29: 1.2750495 | H29: 2.6315572 | I29: 5.8847126 | J29: 9.7913193 | K29: 10.721682 | L29: 1.2224282 | M29: 3.8866691 | N29: 6.930342 | O29: 12.039439 | P29: 13.016595 | Q29: 1.0960058 | R29: 2.8835032 | S29: 7.5191136 | T29: 11.498623 | U29: 12.432983 | V29: 1.1366311 | W29: 2.5957976 | X29: 8.0134927 | Y29: 11.745921 | Z29: 12.711595
A30: Fonte: Fundação Seade. Convênio com a Secretaria Municipal da Fazenda de São Paulo.
A31: Nota: Os dados são preliminares e sujeitos a revisão.
A32: Municípios que compreendem as Delegacias Regionais Tributárias: Região da Capital: município de São Paulo. Região do ABCD: Diadema, Mauá, Ribeirão Pires, Rio Grande da Serra, Santo
A33: André, São Bernardo do Campo e São Caetano do Sul. Região de Guarulhos: Arujá, Biritiba-Mirim, Ferraz de Vasconcelos, Guararema, Guarulhos, Itaquaquecetuba, Mairiporã, Mogi das Cruzes, Poá,
A34: Salesópolis, Santa Isabel e Suzano. Região de Osasco: Barueri, Caieiras, Cajamar, Carapicuíba, Cotia, Embu das Artes, Embu-Guaçu, Francisco Morato, Franco da Rocha, Itapecerica da Serra, Itapevi, Jandira,
A35: Juquitiba, Osasco, Pirapora do Bom Jesus, Santana do Parnaíba, São Lourenço da Serra, Taboão da Serra e Vargem Grande Paulista.

Sheet Tabela 2
A1: Tabela 2
A2: Participação do Valor Adicionado setorial e do Produto Interno Bruto no total da economia paulista, segundo as regiões administrativas
A3: Estado de São Paulo
A4: 2020-2024
Z5: Em porcentagem
A6: Regiões Administrativas | B6: 2020 | G6: 2021 | L6: 2022 | Q6: 2023 | V6: 2024
B7: Valor Adicionado | F7: PIB | G7: Valor Adicionado | K7: PIB | L7: Valor Adicionado | P7: PIB | Q7: Valor Adicionado | U7: PIB | V7: Valor Adicionado | Z7: PIB
B8: Agropecuária | C8: Indústria | D8: Serviços | E8: Total | G8: Agropecuária | H8: Indústria | I8: Serviços | J8: Total | L8: Agropecuária | M8: Indústria | N8: Serviços | O8: Total | Q8: Agropecuária | R8: Indústria | S8: Serviços | T8: Total | V8: Agropecuária | W8: Indústria | X8: Serviços | Y8: Total
A9: Estado de São Paulo | B9: 100 | C9: 100 | D9: 100 | E9: 100 | F9: 100 | G9: 100 | H9: 100 | I9: 100 | J9: 100 | K9: 100 | L9: 100 | M9: 100 | N9: 100 | O9: 100 | P9: 100 | Q9: 100 | R9: 100 | S9: 100 | T9: 100 | U9: 100 | V9: 100 | W9: 100 | X9: 100 | Y9: 100 | Z9: 100
A10: RM São Paulo | B10: 4.5978998 | C10: 34.22316 | D10: 57.003699 | E10: 51.135795 | F10: 52.012022 | G10: 4.2885457 | H10: 32.482068 | I10: 56.192779 | J10: 49.654785 | K10: 51.111394 | L10: 3.8736902 | M10: 30.760519 | N10: 56.24993 | O10: 49.192205 | P10: 50.568403 | Q10: 2.8753108 | R10: 32.635391 | S10: 56.906188 | T10: 50.704681 | U10: 51.862112 | V10: 2.6190803 | W10: 33.428333 | X10: 57.402863 | Y10: 51.431726 | Z10: 52.486559
A11: Município de São Paulo | B11: 0.13943414 | C11: 13.778637 | D11: 36.372519 | E11: 30.899552 | F11: 31.413908 | G11: 0.1334132 | H11: 12.0615 | I11: 35.568609 | J11: 29.416255 | K11: 30.480016 | L11: 0.11394011 | M11: 10.914997 | N11: 35.538727 | O11: 28.965012 | P11: 29.937212 | Q11: 0.09533881 | R11: 12.199506 | S11: 36.681585 | T11: 30.696165 | U11: 31.516101 | V11: 0.089251758 | W11: 12.60446 | X11: 37.265264 | Y11: 31.41373 | Z11: 32.099524
A12: Região do ABCD | B12: 0.036606781 | C12: 7.1204147 | D12: 5.0028873 | E12: 5.3315871 | F12: 5.3499713 | G12: 0.035451222 | H12: 7.4289548 | I12: 5.1029711 | J12: 5.5354268 | K12: 5.5364025 | L12: 0.029487947 | M12: 7.5108058 | N12: 4.9384005 | O12: 5.4865115 | P12: 5.4650272 | Q12: 0.0072175897 | R12: 7.5576239 | S12: 4.8413845 | T12: 5.3713866 | U12: 5.3601889 | V12: 0.0066642305 | W12: 7.8648285 | X12: 4.8226814 | Y12: 5.4020782 | Z12: 5.4144675
A13: Região de Guarulhos | B13: 3.835718 | C13: 6.4543611 | D13: 4.9444234 | E13: 5.2324029 | F13: 5.2323587 | G13: 3.5836703 | H13: 6.6776125 | I13: 4.9800648 | J13: 5.3430164 | K13: 5.325187 | L13: 3.276077 | M13: 6.4759138 | N13: 5.1105571 | O13: 5.4138935 | P13: 5.4186835 | Q13: 2.4255425 | R13: 6.7331553 | S13: 5.0046898 | T13: 5.3494472 | U13: 5.335211 | V13: 2.1946457 | W13: 6.6688274 | X13: 4.8782506 | Y13: 5.2215662 | Z13: 5.2223619
A14: Região de Osasco | B14: 0.58614092 | C14: 6.8697472 | D14: 10.683869 | E14: 9.6722531 | F14: 10.015784 | G14: 0.53601102 | H14: 6.3140003 | I14: 10.541134 | J14: 9.360087 | K14: 9.7697886 | L14: 0.45418514 | M14: 5.8588025 | N14: 10.662246 | O14: 9.3267876 | P14: 9.7474798 | Q14: 0.34721194 | R14: 6.1451065 | S14: 10.378528 | T14: 9.2876829 | U14: 9.6506111 | V14: 0.32851865 | W14: 6.2902164 | X14: 10.436667 | Y14: 9.3943518 | Z14: 9.7502052
A15: RA Campinas | B15: 16.971712 | C15: 28.85317 | D15: 16.18568 | E15: 18.823904 | F15: 19.279076 | G15: 18.664102 | H15: 28.836943 | I15: 16.535391 | J15: 19.41744 | K15: 19.695327 | L15: 19.993206 | M15: 28.675587 | N15: 16.388159 | O15: 19.441898 | P15: 19.711783 | Q15: 19.806027 | R15: 28.42715 | S15: 16.068275 | T15: 18.867714 | U15: 19.140365 | V15: 24.182389 | W15: 27.915335 | X15: 16.000473 | Y15: 18.679473 | Z15: 19.031518
A16: RA São José dos Campos | B16: 1.2888335 | C16: 9.5589465 | D16: 4.2272618 | E16: 5.2656491 | F16: 5.1289047 | G16: 1.3563084 | H16: 11.80485 | I16: 4.4712243 | J16: 6.0992207 | K16: 5.784754 | L16: 1.576529 | M16: 12.963139 | N16: 4.4217853 | O16: 6.4583626 | P16: 5.9068666 | Q16: 1.3035817 | R16: 11.651938 | S16: 4.2962941 | T16: 5.8837873 | U16: 5.4362872 | V16: 1.7623693 | W16: 11.061014 | X16: 4.195984 | Y16: 5.6312598 | Z16: 5.2210682
A17: RA Sorocaba | B17: 9.3938385 | C17: 6.4401114 | D17: 4.1552632 | E17: 4.7434152 | F17: 4.7488021 | G17: 9.3033373 | H17: 6.8579417 | I17: 4.3166794 | J17: 5.005556 | K17: 4.9764843 | L17: 8.5883018 | M17: 6.9315736 | N17: 4.329156 | O17: 5.0322105 | P17: 5.0216983 | Q17: 10.186138 | R17: 6.8116704 | S17: 4.3738246 | T17: 5.0025339 | U17: 5.0145471 | V17: 9.9589264 | W17: 6.900695 | X17: 4.2954647 | Y17: 4.9399386 | Z17: 4.9674936
A18: RA Santos | B18: 0.35407018 | C18: 3.2695209 | D18: 3.0128383 | E18: 3.007368 | F18: 2.8802487 | G18: 0.37986044 | H18: 3.4691504 | I18: 3.0392548 | J18: 3.0837555 | K18: 2.906067 | L18: 0.34926797 | M18: 4.3553608 | N18: 3.0617838 | O18: 3.3334818 | P18: 3.1074542 | Q18: 0.40358624 | R18: 3.5131453 | S18: 3.0142032 | T18: 3.0855895 | U18: 2.9251281 | V18: 0.36707652 | W18: 3.5199267 | X18: 2.9326106 | Y18: 3.0196861 | Z18: 2.86613
A19: RA Ribeirão Preto | B19: 5.1829191 | C19: 2.5108577 | D19: 2.7588406 | E19: 2.7609402 | F19: 2.6278592 | G19: 5.503197 | H19: 2.4570494 | I19: 2.7562242 | J19: 2.743685 | K19: 2.58378 | L19: 5.6236699 | M19: 2.3652188 | N19: 2.7625011 | O19: 2.7117145 | P19: 2.5897193 | Q19: 5.2644274 | R19: 2.4649305 | S19: 2.7117238 | T19: 2.6954297 | U19: 2.5639072 | V19: 5.2221469 | W19: 2.519377 | X19: 2.7630409 | Y19: 2.7480462 | Z19: 2.6125142
A20: RA São José do Rio Preto | B20: 9.8576332 | C20: 2.4242337 | D20: 2.5150734 | E20: 2.65805 | F20: 2.471508 | G20: 9.8762707 | H20: 2.1391054 | I20: 2.5273723 | J20: 2.5889098 | K20: 2.3829535 | L20: 10.240899 | M20: 2.0287689 | N20: 2.5403072 | O20: 2.5395905 | P20: 2.3918191 | Q20: 10.839266 | R20: 2.2024313 | S20: 2.5279198 | T20: 2.5809716 | U20: 2.4309802 | V20: 10.373251 | W20: 2.2305191 | X20: 2.5221201 | Y20: 2.578538 | Z20: 2.4232971
... A29: RA Registro | B29: 2.9171146 | C29: 0.40857318 | D29: 0.34689623 | E29: 0.41628428 | F29: 0.37955184 | G29: 2.7602347 | H29: 0.50773588 | I29: 0.3498891 | J29: 0.43587384 | K29: 0.39421555 | L29: 2.8836115 | M29: 0.60553856 | N29: 0.35568572 | O29: 0.45730546 | P29: 0.41582139 | Q29: 2.6448026 | R29: 0.47260878 | S29: 0.35850982 | T29: 0.41830071 | U29: 0.38428975 | V29: 2.5637054 | W29: 0.41365667 | X29: 0.35545024 | Y29: 0.40138845 | Z29: 0.36517647
A30: Fonte: Fundação Seade. Convênio com a Secretaria Municipal da Fazenda de São Paulo.
A31: Nota: Os dados são preliminares e sujeitos a revisão.
A32: Municípios que compreendem as Delegacias Regionais Tributárias: Região da Capital: município de São Paulo. Região do ABCD: Diadema, Mauá, Ribeirão Pires, Rio Grande da Serra, Santo
A33: André, São Bernardo do Campo e São Caetano do Sul. Região de Guarulhos: Arujá, Biritiba-Mirim, Ferraz de Vasconcelos, Guararema, Guarulhos, Itaquaquecetuba, Mairiporã, Mogi das Cruzes, Poá,
A34: Salesópolis, Santa Isabel e Suzano. Região de Osasco: Barueri, Caieiras, Cajamar, Carapicuíba, Cotia, Embu das Artes, Embu-Guaçu, Francisco Morato, Franco da Rocha, Itapecerica da Serra, Itapevi, Jandira,
A35: Juquitiba, Osasco, Pirapora do Bom Jesus, Santana do Parnaíba, São Lourenço da Serra, Taboão da Serra e Vargem Grande Paulista.

Sheet Tabela 17.1
A1: Tabela 17.1
A2: Produto Interno Bruto a Preço de Mercado Total e per Capita e População Residente
A3: Região Administrativa de São José dos Campos
A4: 2002-2024
A6: Anos | B6: PIB Total | G6: População Residente (1) | H6: PIB per Capita
B7: Preço corrente | C7: Preço do ano anterior | D7: Taxa de crescimento (Em %) | E7: Índice de Volume | F7: Deflator Implícito | H7: Preço Corrente | I7: Preço do ano anterior | J7: Taxa de crescimento (Em %) | K7: Índice de Volume Base:2010=100
B8: Em bilhões de Reais | E8: Base: 2010 = 100 | H8: Em Reais
A9: 2002 | B9: 29.500924 | E9: 66.029997 | F9: 65.716206 | G9: 2048057 | H9: 14404.347 | K9: 72.931938
A10: 2003 | B10: 34.74765 | C10: 28.909265 | D10: -2.0055581 | E10: 64.705727 | F10: 78.987953 | G10: 2075817 | H10: 16739.264 | I10: 13926.693 | J10: -3.3160425 | K10: 70.513484
A11: 2004 | B11: 40.145422 | C11: 37.415472 | D11: 7.6777056 | E11: 69.673642 | F11: 84.751161 | G11: 2103137 | H11: 19088.353 | I11: 17790.316 | J11: 6.2789594 | K11: 74.940997
A12: 2005 | B12: 42.521119 | C12: 40.515125 | D12: 0.92091066 | E12: 70.315274 | F12: 88.94738 | G12: 2130609 | H12: 19957.261 | I12: 19015.749 | J12: -0.38036013 | K12: 74.655952
A13: 2006 | B13: 46.007414 | C13: 45.077367 | D13: 6.0117128 | E13: 74.542426 | F13: 90.782564 | G13: 2157749 | H13: 21321.949 | I13: 20890.922 | J13: 4.6783057 | K13: 78.148585
A14: 2007 | B14: 52.528228 | C14: 51.364824 | D14: 11.644667 | E14: 83.222644 | F14: 92.838771 | G14: 2183874 | H14: 24052.774 | I14: 23520.049 | J14: 10.309097 | K14: 86.204999
A15: 2008 | B15: 59.76027 | C15: 57.420097 | D15: 9.3128396 | E15: 90.973035 | F15: 96.622443 | G15: 2209757 | H15: 27043.82 | I15: 25984.802 | J15: 8.0324525 | K15: 93.129375
A16: 2009 | B16: 62.215158 | C16: 59.131087 | D16: -1.0528463 | E16: 90.015229 | F16: 101.66193 | G16: 2235459 | H16: 27831.044 | I16: 26451.43 | J16: -2.1904828 | K16: 91.089392
A17: 2010 | B17: 67.98637 | C17: 69.116258 | D17: 11.092313 | E17: 100 | F17: 100 | G17: 2262135 | H17: 30054.073 | I17: 30553.551 | J17: 9.7822679 | K17: 100
A18: 2011 | B18: 72.244493 | C18: 69.226912 | D18: 1.8246923 | E18: 101.82469 | F18: 104.35897 | G18: 2285809 | H18: 31605.656 | I18: 30285.519 | J18: 0.77009952 | K18: 100.7701
A19: 2012 | B19: 76.989946 | C19: 74.779354 | D19: 3.5087244 | E19: 105.39744 | F19: 107.44398 | G19: 2309772 | H19: 33332.271 | I19: 32375.21 | J19: 2.434861 | K19: 103.22371
A20: 2013 | B20: 86.603171 | C20: 78.392009 | D20: 1.8210988 | E20: 107.31683 | F20: 118.69819 | G20: 2334029 | H20: 37104.582 | I20: 33586.562 | J20: 0.76289673 | K20: 104.0112
A21: 2014 | B21: 95.839314 | C21: 86.722923 | D21: 0.13827599 | E21: 107.46523 | F21: 131.17585 | G21: 2358600 | H21: 40633.984 | I21: 36768.813 | J21: -0.90492658 | K21: 103.06998
... A31: 2024 | B31: 181.74255 | C31: 175.02295 | D31: -0.48785741 | E31: 105.49162 | F31: 253.40595 | G31: 2554119.3 | H31: 71156.643 | I31: 68525.756 | J31: -1.0511339 | K31: 93.431929
A32: Fonte: Fundação Seade.
A33: (1) Considerou-se a projeção da população estimada pela Fundação Seade.
A34: Nota: Os dados são preliminares e sujeitos a revisão.

Sheet Tabela 17.2
A1: Tabela 17.2
A2: Taxas de crescimento do PIB
A3: Região Administrativa de São José dos Campos
A4: 2º Trimestre de 2002 - 4º trimestre de 2024
A5: Em porcentagem
A6: Trimestres | B6: Trimestre / Trimestre imediatamente anterior (com ajuste sazonal) | C6: Trimestre / mesmo trimestre do ano anterior | D6: Acumulado ao longo do ano / mesmo período do ano anterior | E6: Últimos quatro trimestres / quatro trimestres imediatamente anteriores
A7: 2002.1 | B7: - | C7: - | D7: - | E7: -
A8: 2002.2 | B8: -0.58953666 | C8: - | D8: - | E8: -
A9: 2002.3 | B9: -2.4472924 | C9: - | D9: - | E9: -
A10: 2002.4 | B10: 3.8762023 | C10: - | D10: - | E10: -
A11: 2003.1 | B11: -2.7350912 | C11: -2.0240556 | D11: -2.0240556 | E11: -
A12: 2003.2 | B12: -2.2486795 | C12: -4.1448537 | D12: -3.1011761 | E12: -
A13: 2003.3 | B13: -1.4705075 | C13: -2.1928024 | D13: -2.7942678 | E13: -
A14: 2003.4 | B14: 7.5731961 | C14: 0.16857134 | D14: -2.0055581 | E14: -2.0055581
A15: 2004.1 | B15: 1.2967862 | C15: 5.3859782 | D15: 5.3859782 | E15: -0.26110434
A16: 2004.2 | B16: 0.61926262 | C16: 8.3231593 | D16: 6.8616596 | E16: 2.773523
A17: 2004.3 | B17: 5.7660357 | C17: 15.746595 | D17: 9.8821486 | E17: 7.2422589
A18: 2004.4 | B18: -5.6935166 | C18: 1.7807552 | D18: 7.6777056 | E18: 7.6777056
A19: 2005.1 | B19: 1.2863261 | C19: 0.45422946 | D19: 0.45422946 | E19: 6.4218794
A20: 2005.2 | B20: 2.7997443 | C20: 4.6246949 | D20: 2.5781869 | E20: 5.5226788
A21: 2005.3 | B21: -0.70241205 | C21: -1.8761687 | D21: 0.98308309 | E21: 1.1855698
A22: 2005.4 | B22: -2.0382066 | C22: 0.74135961 | D22: 0.92091066 | E22: 0.92091066
A23: 2006.1 | B23: 3.7449383 | C23: 4.2585928 | D23: 4.2585928 | E23: 1.813627
A24: 2006.2 | B24: 5.1518684 | C24: 5.964674 | D24: 5.14481 | E24: 2.1811098
A25: 2006.3 | B25: -2.2826133 | C25: 4.4235227 | D25: 4.8938305 | E25: 3.8335378
... A98: 2024.4 | B98: -2.1364656 | C98: -2.4327541 | D98: -0.48785741 | E98: -0.48785741
A99: Fonte: Fundação Seade.
A100: Nota: Os dados são preliminares e sujeitos a revisão.

Sheet Tabela 17.7
A1: Tabela 17.7
A2: Taxas de crescimento do Valor Adicionado por setores de atividade econômica e do Produto Interno Bruto acumuladas no ano em relação ao período do ano anterior
A3: Região Administrativa de São José dos Campos
A4: 1º Trimestre de 2003 - 4º trimestre de 2024
A5: Em porcentagem
A6: Trimestres | C6: Valor Adicionado | G6: PIB
C7: Agropecuária | D7: Indústria | E7: Serviços | F7: Total
A8: 2003 | B8: I | C8: 23.460327 | D8: 4.3718366 | E8: -1.0741346 | F8: 1.4515026 | G8: -2.0240556
B9: II | C9: 16.804139 | D9: 0.56370595 | E9: -1.8093105 | F9: -0.61232337 | G9: -3.1011761
B10: III | C10: 11.86149 | D10: -2.1102379 | E10: -0.44696922 | F10: -1.0683596 | G10: -2.7942678
B11: IV | C11: 8.6178739 | D11: -4.4817746 | E11: 1.280153 | F11: -1.2384266 | G11: -2.0055581
A12: 2004 | B12: I | C12: -14.058089 | D12: 7.3024193 | E12: 2.0253388 | F12: 4.4022929 | G12: 5.3859782
B13: II | C13: -14.955929 | D13: 10.984526 | E13: 1.3374732 | F13: 5.8248179 | G13: 6.8616596
B14: III | C14: -12.47223 | D14: 15.148086 | E14: 3.6007282 | F14: 9.064236 | G14: 9.8821486
B15: IV | C15: -11.049105 | D15: 14.99244 | E15: 0.3249941 | F15: 7.2492533 | G15: 7.6777056
A16: 2005 | B16: I | C16: 1.4016061 | D16: 1.4913731 | E16: -0.9602196 | F16: 0.30116725 | G16: 0.45422946
B17: II | C17: 2.5816648 | D17: 2.7635397 | E17: 1.7867806 | F17: 2.2984049 | G17: 2.5781869
B18: III | C18: 1.2723764 | D18: 0.92847244 | E18: 0.63829885 | F18: 0.80909392 | G18: 0.98308309
B19: IV | C19: -2.2942277 | D19: -0.26742947 | E19: 1.7536583 | F19: 0.69492814 | G19: 0.92091066
A20: 2006 | B20: I | C20: 15.695198 | D20: 2.1930169 | E20: 4.7923371 | F20: 3.6647066 | G20: 4.2585928
B21: II | C21: 17.35556 | D21: 4.2193233 | E21: 4.3244956 | F21: 4.3765371 | G21: 5.14481
B22: III | C22: 18.291884 | D22: 4.7142261 | E22: 2.5333461 | F22: 3.7060317 | G22: 4.8938305
B23: IV | C23: 18.791305 | D23: 5.575767 | E23: 3.2649609 | F23: 4.502587 | G23: 6.0117128
A24: 2007 | B24: I | C24: -12.010973 | D24: 9.4635717 | E24: 6.0265396 | F24: 7.7033688 | G24: 10.329029
B25: II | C25: -16.930286 | D25: 6.7955052 | E25: 5.5414235 | F25: 6.0543996 | G25: 8.5264819
B26: III | C26: -16.215083 | D26: 8.4497204 | E26: 8.8927944 | F26: 8.4916854 | G26: 10.741059
B27: IV | C27: -16.717029 | D27: 10.555675 | E27: 9.4986751 | F27: 9.800566 | G27: 11.644667
A28: 2008 | B28: I | C28: 6.7417985 | D28: 12.48584 | E28: 9.8281435 | F28: 10.978535 | G28: 11.859711
B29: II | C29: 18.596536 | D29: 11.635092 | E29: 12.194733 | F29: 11.95719 | G29: 12.777974
B30: III | C30: 19.586696 | D30: 9.5345292 | E30: 11.126703 | F30: 10.422783 | G30: 11.395767
B31: IV | C31: 31.970645 | D31: 6.6962532 | E31: 9.0512125 | F31: 8.0876975 | G31: 9.3128396
A32: 2009 | B32: I | C32: 14.164298 | D32: -8.1907828 | E32: 3.4205718 | F32: -2.0259854 | G32: 0.075137932
B33: II | C33: 7.0663397 | D33: -7.2554332 | E33: 1.0387918 | F33: -2.8673321 | G33: -0.65425397
B34: III | C34: 7.0212088 | D34: -6.6084842 | E34: -0.96696309 | F34: -3.600533 | G34: -1.4397284
B35: IV | C35: -0.23754929 | D35: -5.9500177 | E35: -0.40328121 | F35: -3.0598307 | G35: -1.0528463
A36: 2010 | B36: I | C36: -1.2934844 | D36: 5.9608546 | E36: 15.135871 | F36: 11.096984 | G36: 11.94419
B37: II | C37: -3.6386859 | D37: 5.3852661 | E37: 16.239744 | F37: 11.319973 | G37: 12.488355
B38: III | C38: -5.5892397 | D38: 2.9224915 | E38: 15.921689 | F38: 9.8795372 | G38: 11.195112
B39: IV | C39: -9.3443071 | D39: 1.8163909 | E39: 16.532814 | F39: 9.6625845 | G39: 11.092313
A40: 2011 | B40: I | C40: -6.6537913 | D40: 0.72791968 | E40: 3.9118393 | F40: 2.4015945 | G40: 3.8029533
...

Sheet Tabela 17.8
A1: Tabela 17.8
A2: Taxas de crescimento do Valor Adicionado por setores de atividade econômica e do Produto Interno Bruto acumuladas nos últimos quatro trimestres em relação aos quatro trimestres imediatamente anteriores
A3: Região Administrativa de São José dos Campos
A4: 4º Trimestre de 2003 - 4º trimestre de 2024
A5: Em porcentagem
A6: Trimestres | C6: Valor Adicionado | G6: PIB
C7: Agropecuária | D7: Indústria | E7: Serviços | F7: Total
A8: 2003 | B8: IV | C8: 8.6178739 | D8: -4.4817746 | E8: 1.280153 | F8: -1.2384266 | G8: -2.0055581
A9: 2004 | B9: I | C9: -0.61397921 | D9: -3.7264594 | E9: 2.0438356 | F9: -0.52834238 | G9: -0.26110434
B10: II | C10: -7.4298751 | D10: 0.35406255 | E10: 2.861337 | F10: 1.8494248 | G10: 2.773523
B11: III | C11: -9.201673 | D11: 7.842083 | E11: 4.2868099 | F11: 6.158821 | G11: 7.2422589
B12: IV | C12: -11.049105 | D12: 14.99244 | E12: 0.3249941 | F12: 7.2492533 | G12: 7.6777056
A13: 2005 | B13: I | C13: -7.3790178 | D13: 13.377217 | E13: -0.39622412 | F13: 6.1968369 | G13: 6.4218794
B14: II | C14: -2.2634163 | D14: 10.581718 | E14: 0.54996095 | F14: 5.4514763 | G14: 5.5226788
B15: III | C15: -1.0621851 | D15: 4.1340137 | E15: -1.7730096 | F15: 1.1697237 | G15: 1.1855698
B16: IV | C16: -2.2942277 | D16: -0.26742947 | E16: 1.7536583 | F16: 0.69492814 | G16: 0.92091066
A17: 2006 | B17: I | C17: 1.3189581 | D17: -0.10137233 | E17: 3.1576218 | F17: 1.4866867 | G17: 1.813627
B18: II | C18: 5.2430842 | D18: 0.46376443 | E18: 3.0030502 | F18: 1.717765 | G18: 2.1811098
B19: III | C19: 10.212858 | D19: 2.5466646 | E19: 3.1783021 | F19: 2.8610362 | G19: 3.8335378
B20: IV | C20: 18.791305 | D20: 5.575767 | E20: 3.2649609 | F20: 4.502587 | G20: 6.0117128
A21: 2007 | B21: I | C21: 10.701556 | D21: 7.2565151 | E21: 3.5867981 | F21: 5.4668853 | G21: 7.4539768
B22: II | C22: -0.67284301 | D22: 6.8198043 | E22: 3.8935334 | F22: 5.3329368 | G22: 7.6718812
B23: III | C23: -8.4148722 | D23: 8.3736225 | E23: 8.0201795 | F23: 8.0877346 | G23: 10.371138
B24: IV | C24: -16.717029 | D24: 10.555675 | E24: 9.4986751 | F24: 9.800566 | G24: 11.644667
A25: 2008 | B25: I | C25: -12.576783 | D25: 11.253406 | E25: 10.409146 | F25: 10.568205 | G25: 11.992122
B26: II | C26: 0.067196454 | D26: 12.82504 | E26: 12.762944 | F26: 12.644176 | G26: 13.652383
B27: III | C27: 8.9783697 | D27: 11.253017 | E27: 11.14995 | F27: 11.183838 | G27: 12.072679
B28: IV | C28: 31.970645 | D28: 6.6962532 | E28: 9.0512125 | F28: 8.0876975 | G28: 9.3128396
A29: 2009 | B29: I | C29: 33.597708 | D29: 1.8691027 | E29: 7.4585806 | F29: 4.9520293 | G29: 6.4737523
B30: II | C30: 24.349771 | D30: -2.2730121 | E30: 3.6020467 | F30: 0.92816851 | G30: 2.8287821
B31: III | C31: 20.445615 | D31: -5.1570894 | E31: 0.068218813 | F31: -2.281959 | G31: -0.15682634
B32: IV | C32: -0.23754929 | D32: -5.9500177 | E32: -0.40328121 | F32: -3.0598307 | G32: -1.0528463
A33: 2010 | B33: I | C33: -3.498444 | D33: -2.8335252 | E33: 2.4605174 | F33: -0.044487129 | G33: 1.6979765
B34: II | C34: -5.159977 | D34: -0.047317528 | E34: 7.074057 | F34: 3.7206658 | G34: 5.2597978
B35: III | C35: -8.7521535 | D35: 1.0825208 | E35: 12.232762 | F35: 6.9456043 | G35: 8.3085319
B36: IV | C36: -9.3443071 | D36: 1.8163909 | E36: 16.532814 | F36: 9.6625845 | G36: 11.092313
A37: 2011 | B37: I | C37: -10.67784 | D37: 0.63240143 | E37: 13.432705 | F37: 7.4749148 | G37: 9.0386968
B38: II | C38: -11.523521 | D38: -1.6983111 | E38: 9.3780314 | F38: 4.2700076 | G38: 5.6351133
B39: III | C39: -10.821661 | D39: -1.0828379 | E39: 6.5920735 | F39: 3.1137184 | G39: 4.2049537
B40: IV | C40: -3.3191977 | D40: -1.4604691 | E40: 2.9914251 | F40: 0.97715244 | G40: 1.8246923
...

Sheet Tabela 17.9
A1: Tabela 17.9
A2: Valor Adicionado por setores de atividade econômica e do Produto Interno Bruto
A3: Região Administrativa de São José dos Campos
A4: 1º Trimestre de 2002 - 4º trimestre de 2024
A5: Em bilhões Reais
A6: Trimestres | C6: Valor Adicionado | G6: PIB
C7: Agropecuária | D7: Indústria | E7: Serviços | F7: Total
A8: 2002 | B8: I | C8: 0.039288665 | D8: 2.7090968 | E8: 3.0954184 | F8: 5.8438038 | G8: 6.8183052
B9: II | C9: 0.05377859 | D9: 2.5660736 | E9: 3.2003211 | F9: 5.8201733 | G9: 6.9554343
B10: III | C10: 0.058038977 | D10: 2.6466557 | E10: 3.3252185 | F10: 6.0299132 | G10: 7.295626
B11: IV | C11: 0.078535353 | D11: 3.0881904 | E11: 3.6587084 | F11: 6.8254342 | G11: 8.431558
A12: 2003 | B12: I | C12: 0.097157257 | D12: 3.1415758 | E12: 3.6968072 | F12: 6.9355402 | G12: 8.321337
B13: II | C13: 0.092348783 | D13: 3.4734624 | E13: 3.5225212 | F13: 7.0883324 | G13: 8.2696131
B14: III | C14: 0.071909751 | D14: 3.7438679 | E14: 3.6045106 | F14: 7.4202883 | G14: 8.4951543
B15: IV | C15: 0.085258744 | D15: 3.9032272 | E15: 4.2089297 | F15: 8.1974157 | G15: 9.6615452
A16: 2004 | B16: I | C16: 0.057699321 | D16: 3.7172695 | E16: 3.9080082 | F16: 7.682977 | G16: 9.1668328
B17: II | C17: 0.056718081 | D17: 4.0286557 | E17: 3.771151 | F17: 7.8565248 | G17: 9.5051736
B18: III | C18: 0.054672323 | D18: 4.6047987 | E18: 4.145546 | F18: 8.8050171 | G18: 10.504008
B19: IV | C19: 0.063404081 | D19: 4.6299735 | E19: 4.266707 | F19: 8.9600846 | G19: 10.969408
A20: 2005 | B20: I | C20: 0.059591763 | D20: 3.9226193 | E20: 4.1069039 | F20: 8.0891149 | G20: 9.796412
B21: II | C21: 0.061952948 | D21: 4.431922 | E21: 4.2946792 | F21: 8.7885542 | G21: 10.57769
B22: III | C22: 0.054325851 | D22: 4.6396448 | E22: 4.4267325 | F22: 9.1207031 | G22: 10.789597
B23: IV | C23: 0.055098613 | D23: 4.4327563 | E23: 4.9496692 | F23: 9.4375242 | G23: 11.357421
A24: 2006 | B24: I | C24: 0.065154483 | D24: 3.7893238 | E24: 4.8020871 | F24: 8.6565653 | G24: 10.498381
B25: II | C25: 0.067877265 | D25: 4.3722173 | E25: 4.8022023 | F25: 9.2422969 | G25: 11.295868
B26: III | C26: 0.061672009 | D26: 4.6430741 | E26: 4.775896 | F26: 9.4806421 | G26: 11.510494
B27: IV | C27: 0.075362032 | D27: 4.6181579 | E27: 5.4766576 | F27: 10.170178 | G27: 12.702672
A28: 2007 | B28: I | C28: 0.079900818 | D28: 4.44195 | E28: 5.1327135 | F28: 9.6545643 | G28: 11.770188
B29: II | C29: 0.072808334 | D29: 5.0217452 | E29: 5.246447 | F29: 10.341001 | G29: 12.542464
B30: III | C30: 0.082317452 | D30: 5.6394914 | E30: 5.6648903 | F30: 11.386699 | G30: 13.64408
B31: IV | C31: 0.07830715 | D31: 5.6994473 | E31: 6.2310282 | F31: 12.008783 | G31: 14.571496
A32: 2008 | B32: I | C32: 0.051720105 | D32: 5.1535136 | E32: 5.7935774 | F32: 10.998811 | G32: 13.474528
B33: II | C33: 0.05888928 | D33: 5.6573707 | E33: 6.1372056 | F33: 11.853466 | G33: 14.566809
B34: III | C34: 0.052056455 | D34: 6.2552951 | E34: 6.4215263 | F34: 12.728878 | G34: 15.473989
B35: IV | C35: 0.069505802 | D35: 6.2418864 | E35: 6.7589932 | F35: 13.070385 | G35: 16.244945
A36: 2009 | B36: I | C36: 0.071459043 | D36: 5.2282218 | E36: 6.7976869 | F36: 12.097368 | G36: 14.45586
B37: II | C37: 0.079844763 | D37: 5.8725629 | E37: 6.7987374 | F37: 12.751145 | G37: 15.094344
B38: III | C38: 0.080704152 | D38: 6.4425825 | E38: 6.8177921 | F38: 13.341079 | G38: 15.747191
B39: IV | C39: 0.083125193 | D39: 6.3199585 | E39: 7.7108944 | F39: 14.113978 | G39: 16.917763
A40: 2010 | B40: I | C40: 0.075584746 | D40: 5.729322 | E40: 7.1574739 | F40: 12.962381 | G40: 15.697052
...

Sheet Tabela 20.2
A1: Tabela 20.2
A2: Taxas de crescimento do PIB
A3: Região Metropolitana de São Paulo
A4: 2º Trimestre de 2002 - 4º trimestre de 2024
A5: Em porcentagem
A6: Trimestres | B6: Trimestre / Trimestre imediatamente anterior (com ajuste sazonal) | C6: Trimestre / mesmo trimestre do ano anterior | D6: Acumulado ao longo do ano / mesmo período do ano anterior | E6: Últimos quatro trimestres / quatro trimestres imediatamente anteriores
A7: 2002.1 | B7: - | C7: - | D7: - | E7: -
A8: 2002.2 | B8: -1.2626931 | C8: - | D8: - | E8: -
A9: 2002.3 | B9: -2.575341 | C9: - | D9: - | E9: -
A10: 2002.4 | B10: -1.0544463 | C10: - | D10: - | E10: -
A11: 2003.1 | B11: -0.49624378 | C11: -5.0431414 | D11: -5.0431414 | E11: -
A12: 2003.2 | B12: -0.25068061 | C12: -4.8117634 | D12: -4.9262402 | E12: -
A13: 2003.3 | B13: 2.2329864 | C13: 0.45505853 | D13: -3.1331582 | E13: -
A14: 2003.4 | B14: 2.6246424 | C14: 3.8571635 | D14: -1.3848791 | E14: -1.3848791
A15: 2004.1 | B15: 1.1386445 | C15: 6.6025654 | D15: 6.6025654 | E15: 1.4316926
A16: 2004.2 | B16: 1.5219899 | C16: 7.8914696 | D16: 7.2545543 | E16: 4.6415017
A17: 2004.3 | B17: 0.44545374 | C17: 5.7465764 | D17: 6.7334739 | E17: 5.9968003
A18: 2004.4 | B18: 0.29166058 | C18: 3.5072623 | D18: 5.8837078 | E18: 5.8837078
A19: 2005.1 | B19: 1.6838255 | C19: 2.7944828 | D19: 2.7944828 | E19: 4.9427677
A20: 2005.2 | B20: 0.53266641 | C20: 3.6483929 | D20: 3.2289961 | E20: 3.9189682
A21: 2005.3 | B21: 1.2324397 | C21: 3.8676002 | D21: 3.4476247 | E21: 3.4625906
A22: 2005.4 | B22: 0.87842737 | C22: 3.9739322 | D22: 3.5831399 | E22: 3.5831399
A23: 2006.1 | B23: 1.2597938 | C23: 4.7227582 | D23: 4.7227582 | E23: 4.050115
A24: 2006.2 | B24: -0.1563584 | C24: 2.8931994 | D24: 3.7880025 | E24: 3.855053
A25: 2006.3 | B25: 0.64762563 | C25: 2.4499063 | D25: 3.3280401 | E25: 3.4901952
... A98: 2024.4 | B98: -0.34748233 | C98: 3.8342092 | D98: 4.5073585 | E98: 4.5073585
A99: Fonte: Fundação Seade.
A100: Nota: Os dados são preliminares e sujeitos a revisão.

Sheet Tabela 20.3
A1: Tabela 20.3
A2: Índices trimestrais do Valor Adicionado por setores de atividade econômica e do Produto Interno Bruto
A3: Região Metropolitana de São Paulo
A4: 1º Trimestre de 2002 - 4º trimestre de 2024
A5: Base: 2010 = 100
A6: Trimestres | C6: Valor Adicionado | G6: PIB
C7: Agropecuária | D7: Indústria | E7: Serviços | F7: Total
A8: 2002 | B8: I | C8: 195.50833 | D8: 74.484763 | E8: 73.247163 | F8: 73.735485 | G8: 74.125585
B9: II | C9: 224.4282 | D9: 86.542893 | E9: 72.011976 | F9: 75.208996 | G9: 75.695431
B10: III | C10: 186.54743 | D10: 90.727363 | E10: 70.707739 | F10: 74.99255 | G10: 74.867651
B11: IV | C11: 173.42058 | D11: 90.09019 | E11: 70.124722 | F11: 74.389868 | G11: 74.936153
A12: 2003 | B12: I | C12: 208.57086 | D12: 80.702236 | E12: 67.19151 | F12: 70.164407 | G12: 70.387327
B13: II | C13: 224.64233 | D13: 79.254328 | E13: 69.078792 | F13: 71.388447 | G13: 72.053146
B14: III | C14: 181.27885 | D14: 84.386035 | E14: 72.173909 | F14: 74.87596 | G14: 75.208343
B15: IV | C15: 165.74272 | D15: 85.366758 | E15: 74.069522 | F15: 76.580222 | G15: 77.826563
A16: 2004 | B16: I | C16: 209.79468 | D16: 81.999049 | E16: 72.070507 | F16: 74.296044 | G16: 75.034697
B17: II | C17: 226.70812 | D17: 86.969753 | E17: 74.123609 | F17: 76.990124 | G17: 77.739198
B18: III | C18: 185.75341 | D18: 93.12056 | E18: 75.441133 | F18: 79.332076 | G18: 79.530248
B19: IV | C19: 164.09106 | D19: 89.044347 | E19: 77.2063 | F19: 79.817064 | G19: 80.556145
A20: 2005 | B20: I | C20: 147.57699 | D20: 83.70439 | E20: 74.698023 | F20: 76.655755 | G20: 77.131528
B21: II | C21: 157.606 | D21: 90.133769 | E21: 77.062179 | F21: 79.935484 | G21: 80.575429
B22: III | C22: 132.66406 | D22: 94.028016 | E22: 78.966192 | F22: 82.270801 | G22: 82.60616
B23: IV | C23: 131.92487 | D23: 90.191142 | E23: 80.705596 | F23: 82.751328 | G23: 83.757392
A24: 2006 | B24: I | C24: 134.38688 | D24: 86.806219 | E24: 78.311657 | F24: 80.153816 | G24: 80.774264
B25: II | C25: 139.1681 | D25: 88.162994 | E25: 80.415118 | F25: 82.092595 | G25: 82.906637
B26: III | C26: 129.20373 | D26: 90.808676 | E26: 82.475536 | F26: 84.272266 | G26: 84.629934
B27: IV | C27: 115.88577 | D27: 86.891964 | E27: 85.137008 | F27: 85.470389 | G27: 86.19096
A28: 2007 | B28: I | C28: 127.80085 | D28: 84.574136 | E28: 83.096741 | F28: 83.446402 | G28: 83.876293
B29: II | C29: 128.69045 | D29: 91.838108 | E29: 87.661524 | F29: 88.570023 | G29: 89.002288
B30: III | C30: 117.56988 | D30: 97.154382 | E30: 89.761367 | F30: 91.329165 | G30: 91.263351
B31: IV | C31: 109.90327 | D31: 95.067272 | E31: 92.638723 | F31: 93.168179 | G31: 93.986228
A32: 2008 | B32: I | C32: 101.23969 | D32: 92.815027 | E32: 89.088572 | F32: 89.877079 | G32: 90.259454
B33: II | C33: 101.28979 | D33: 100.50859 | E33: 93.620216 | F33: 95.078332 | G33: 95.542619
B34: III | C34: 94.535336 | D34: 105.07825 | E34: 97.320258 | F34: 98.95315 | G34: 98.85137
B35: IV | C35: 89.618383 | D35: 91.122653 | E35: 96.395718 | F35: 95.243667 | G35: 95.420673
A36: 2009 | B36: I | C36: 104.01605 | D36: 80.020494 | E36: 90.787702 | F36: 88.512544 | G36: 87.621292
B37: II | C37: 113.26106 | D37: 88.766635 | E37: 93.851281 | F37: 92.781403 | G37: 92.437547
B38: III | C38: 100.88737 | D38: 96.904662 | E38: 96.446047 | F38: 96.534237 | G38: 96.467088
B39: IV | C39: 88.405223 | D39: 97.997572 | E39: 98.442632 | F39: 98.327442 | G39: 99.274104
A40: 2010 | B40: I | C40: 107.34211 | D40: 96.819929 | E40: 96.378378 | F40: 96.483706 | G40: 96.411342
...
